Workbook

Sheet Balanço
A1: Bioestatística - 3.º Ano _ T.ª A - Licenciatura em Enfrmagem - 2026/2027 | K1: Pesos | L1: Presença | M1: 0.1
L2: Teste | M2: 0.7
A3: Total de alunos: 31 | L3: Ficha | M3: 0.2
E5: Média | I5: Média | K5: Média
A6: N.º | B6: Nome | C6: Ficha 1 | D6: Ficha 2 | E6: Fichas | F6: Teste 1 | G6: Teste 2 | H6: Teste 3 | I6: Testes | J6: Presença | K6: Final | L6: Avaliação contínua | M6: Exame
A7: 1 | B7: Adelino Ceita | C7: ='Ficha 1'!T6 -> 0 | D7: ='Ficha 2'!Q6 -> 0 | E7: =AVERAGE(C7:D7) -> 0 | F7: ='Teste 1'!R5 -> 0 | G7: ='Teste 2'!O5 -> 0 | H7: ='Teste 3'!O5 -> 0 | I7: =AVERAGE(F7:H7) -> 0 | J7: =Presenças!AH7 -> 0 | K7: =$M$3*E7+$M$2*I7+$M$1*J7 -> 0
A8: 2 | B8: Adilson Santos | C8: ='Ficha 1'!T7 -> 0 | D8: ='Ficha 2'!Q7 -> 0 | E8: =AVERAGE(C8:D8) -> 0 | F8: ='Teste 1'!R6 -> 0 | G8: ='Teste 2'!O6 -> 0 | H8: ='Teste 3'!O6 -> 0 | I8: =AVERAGE(F8:H8) -> 0 | J8: =Presenças!AH8 -> 0 | K8: =$M$3*E8+$M$2*I8+$M$1*J8 -> 0
A9: 3 | B9: Admilson Fonseca | C9: ='Ficha 1'!T8 -> 0 | D9: ='Ficha 2'!Q8 -> 0 | E9: =AVERAGE(C9:D9) -> 0 | F9: ='Teste 1'!R7 -> 0 | G9: ='Teste 2'!O7 -> 0 | H9: ='Teste 3'!O7 -> 0 | I9: =AVERAGE(F9:H9) -> 0 | J9: =Presenças!AH9 -> 0 | K9: =$M$3*E9+$M$2*I9+$M$1*J9 -> 0
A10: 4 | B10: Admilton Barros | C10: ='Ficha 1'!T9 -> 0 | D10: ='Ficha 2'!Q9 -> 0 | E10: =AVERAGE(C10:D10) -> 0 | F10: ='Teste 1'!R8 -> 0 | G10: ='Teste 2'!O8 -> 0 | H10: ='Teste 3'!O8 -> 0 | I10: =AVERAGE(F10:H10) -> 0 | J10: =Presenças!AH10 -> 0 | K10: =$M$3*E10+$M$2*I10+$M$1*J10 -> 0
A11: 5 | B11: Adnalda Cosme | C11: ='Ficha 1'!T10 -> 0 | D11: ='Ficha 2'!Q10 -> 0 | E11: =AVERAGE(C11:D11) -> 0 | F11: ='Teste 1'!R9 -> 0 | G11: ='Teste 2'!O9 -> 0 | H11: ='Teste 3'!O9 -> 0 | I11: =AVERAGE(F11:H11) -> 0 | J11: =Presenças!AH11 -> 0 | K11: =$M$3*E11+$M$2*I11+$M$1*J11 -> 0
A12: 6 | B12: Alex Santos | C12: ='Ficha 1'!T11 -> 0 | D12: ='Ficha 2'!Q11 -> 0 | E12: =AVERAGE(C12:D12) -> 0 | F12: ='Teste 1'!R10 -> 0 | G12: ='Teste 2'!O10 -> 0 | H12: ='Teste 3'!O10 -> 0 | I12: =AVERAGE(F12:H12) -> 0 | J12: =Presenças!AH12 -> 0 | K12: =$M$3*E12+$M$2*I12+$M$1*J12 -> 0
A13: 7 | B13: Anazilsa Sacramento | C13: ='Ficha 1'!T12 -> 0 | D13: ='Ficha 2'!Q12 -> 0 | E13: =AVERAGE(C13:D13) -> 0 | F13: ='Teste 1'!R11 -> 0 | G13: ='Teste 2'!O11 -> 0 | H13: ='Teste 3'!O11 -> 0 | I13: =AVERAGE(F13:H13) -> 0 | J13: =Presenças!AH13 -> 0 | K13: =$M$3*E13+$M$2*I13+$M$1*J13 -> 0
A14: 8 | B14: Anylson Oliveira | C14: ='Ficha 1'!T13 -> 0 | D14: ='Ficha 2'!Q13 -> 0 | E14: =AVERAGE(C14:D14) -> 0 | F14: ='Teste 1'!R12 -> 0 | G14: ='Teste 2'!O12 -> 0 | H14: ='Teste 3'!O12 -> 0 | I14: =AVERAGE(F14:H14) -> 0 | J14: =Presenças!AH14 -> 0 | K14: =$M$3*E14+$M$2*I14+$M$1*J14 -> 0
A15: 9 | B15: Atanásio Quaresma | C15: ='Ficha 1'!T14 -> 0 | D15: ='Ficha 2'!Q14 -> 0 | E15: =AVERAGE(C15:D15) -> 0 | F15: ='Teste 1'!R13 -> 0 | G15: ='Teste 2'!O13 -> 0 | H15: ='Teste 3'!O13 -> 0 | I15: =AVERAGE(F15:H15) -> 0 | J15: =Presenças!AH15 -> 0 | K15: =$M$3*E15+$M$2*I15+$M$1*J15 -> 0
A16: 10 | B16: Carla Nascimento | C16: ='Ficha 1'!T15 -> 0 | D16: ='Ficha 2'!Q15 -> 0 | E16: =AVERAGE(C16:D16) -> 0 | F16: ='Teste 1'!R14 -> 0 | G16: ='Teste 2'!O14 -> 0 | H16: ='Teste 3'!O14 -> 0 | I16: =AVERAGE(F16:H16) -> 0 | J16: =Presenças!AH16 -> 0 | K16: =$M$3*E16+$M$2*I16+$M$1*J16 -> 0
A17: 11 | B17: Celeste Cruz | C17: ='Ficha 1'!T16 -> 0 | D17: ='Ficha 2'!Q16 -> 0 | E17: =AVERAGE(C17:D17) -> 0 | F17: ='Teste 1'!R15 -> 0 | G17: ='Teste 2'!O15 -> 0 | H17: ='Teste 3'!O15 -> 0 | I17: =AVERAGE(F17:H17) -> 0 | J17: =Presenças!AH17 -> 0 | K17: =$M$3*E17+$M$2*I17+$M$1*J17 -> 0
A18: 12 | B18: Célia Assunção | C18: ='Ficha 1'!T17 -> 0 | D18: ='Ficha 2'!Q17 -> 0 | E18: =AVERAGE(C18:D18) -> 0 | F18: ='Teste 1'!R16 -> 0 | G18: ='Teste 2'!O16 -> 0 | H18: ='Teste 3'!O16 -> 0 | I18: =AVERAGE(F18:H18) -> 0 | J18: =Presenças!AH18 -> 0 | K18: =$M$3*E18+$M$2*I18+$M$1*J18 -> 0
... A44: 38 | B44: Yara Paquete | C44: ='Ficha 1'!T43 -> 0 | D44: ='Ficha 2'!Q43 -> 0 | E44: =AVERAGE(C44:D44) -> 0 | F44: ='Teste 1'!R42 -> 0 | G44: ='Teste 2'!O42 -> 0 | H44: ='Teste 3'!O42 -> 0 | I44: =AVERAGE(F44:H44) -> 0 | J44: =Presenças!AH44 -> 0 | K44: =$M$3*E44+$M$2*I44+$M$1*J44 -> 0
B48: Nº de Ordem | C48: Nome do Aluno
B49: 170 | C49: Márcia Rodrigues Cesário Garcês
B50: 175 | C50: Henrique Quaresma Luís Lopes de Andrade
B51: 179 | C51: Dalton Martins da Graça Viegas
B52: 185 | C52: Rosalda Esterze da Graça Neto
B53: 186 | C53: Sofia Mandú da Graça
B54: 187 | C54: Kely Paulina Sequeira Bragança
B55: 191 | C55: Jussara Oliveira Teixeira da Trindade
B56: 193 | C56: Narla de Sousa Leal Martins
B57: 194 | C57: Itelma Carvalho de Assunção Gonçalves
B58: 75 | C58: Eurikcy Tomé Costa
B59: 119 | C59: Abigail do Nascimento
B60: 126 | C60: Betnilda Jordão Lima Dias Viana
... B65: 162 | C65: Virtude dos Santos Silva
B69: Nº de Ordem | C69: Nome do Aluno
B70: 234 | C70: Elizângela Luís Tebús
B71: 238 | C71: Celmira Menezes
B72: 239 | C72: Yola da Cruz
B73: 242 | C73: Derley dos Ramos
B74: 243 | C74: Sadam de Assunção Sacramento
B75: 244 | C75: Jucilene Dias dos Ramos
B76: 245 | C76: Renilton da Cruz dos Santos
...

Sheet Balanço - Relatório
A1: Álgebra Linear - 1.º Ano - Licenciatura em Matemática - 2025/2026 | K1: Pesos | L1: Presença | M1: 0.1
L2: Teste | M2: 0.7
A3: Total de alunos: 31 | L3: Ficha | M3: 0.2
E5: Média | I5: Média | K5: Média
A6: N.º | B6: Nome | C6: Ficha 1 | D6: Ficha 2 | E6: Fichas | F6: Teste 1 | G6: Teste 2 | H6: Teste 3 | I6: Testes | J6: Presença | K6: Final | L6: Avaliação contínua | M6: Exame
A7: 1 | B7: Adelino Ceita | C7: ='Ficha 1'!T6 -> 0 | D7: ='Ficha 2'!Q6 -> 0 | E7: =AVERAGE(C7:D7) -> 0 | F7: ='Teste 1'!R5 -> 0 | G7: ='Teste 2'!O5 -> 0 | H7: ='Teste 3'!O5 -> 0 | I7: =AVERAGE(F7:H7) -> 0 | J7: =Presenças!AH7 -> 0 | K7: =$M$3*E7+$M$2*I7+$M$1*J7 -> 0
A8: 2 | B8: Adilson Santos | C8: ='Ficha 1'!T7 -> 0 | D8: ='Ficha 2'!Q7 -> 0 | E8: =AVERAGE(C8:D8) -> 0 | F8: ='Teste 1'!R6 -> 0 | G8: ='Teste 2'!O6 -> 0 | H8: ='Teste 3'!O6 -> 0 | I8: =AVERAGE(F8:H8) -> 0 | J8: =Presenças!AH8 -> 0 | K8: =$M$3*E8+$M$2*I8+$M$1*J8 -> 0
A9: 3 | B9: Admilson Fonseca | C9: ='Ficha 1'!T8 -> 0 | D9: ='Ficha 2'!Q8 -> 0 | E9: =AVERAGE(C9:D9) -> 0 | F9: ='Teste 1'!R7 -> 0 | G9: ='Teste 2'!O7 -> 0 | H9: ='Teste 3'!O7 -> 0 | I9: =AVERAGE(F9:H9) -> 0 | J9: =Presenças!AH9 -> 0 | K9: =$M$3*E9+$M$2*I9+$M$1*J9 -> 0
A10: 4 | B10: Admilton Barros | C10: ='Ficha 1'!T9 -> 0 | D10: ='Ficha 2'!Q9 -> 0 | E10: =AVERAGE(C10:D10) -> 0 | F10: ='Teste 1'!R8 -> 0 | G10: ='Teste 2'!O8 -> 0 | H10: ='Teste 3'!O8 -> 0 | I10: =AVERAGE(F10:H10) -> 0 | J10: =Presenças!AH10 -> 0 | K10: =$M$3*E10+$M$2*I10+$M$1*J10 -> 0
A11: 5 | B11: Adnalda Cosme | C11: ='Ficha 1'!T10 -> 0 | D11: ='Ficha 2'!Q10 -> 0 | E11: =AVERAGE(C11:D11) -> 0 | F11: ='Teste 1'!R9 -> 0 | G11: ='Teste 2'!O9 -> 0 | H11: ='Teste 3'!O9 -> 0 | I11: =AVERAGE(F11:H11) -> 0 | J11: =Presenças!AH11 -> 0 | K11: =$M$3*E11+$M$2*I11+$M$1*J11 -> 0
A12: 6 | B12: Alex Santos | C12: ='Ficha 1'!T11 -> 0 | D12: ='Ficha 2'!Q11 -> 0 | E12: =AVERAGE(C12:D12) -> 0 | F12: ='Teste 1'!R10 -> 0 | G12: ='Teste 2'!O10 -> 0 | H12: ='Teste 3'!O10 -> 0 | I12: =AVERAGE(F12:H12) -> 0 | J12: =Presenças!AH12 -> 0 | K12: =$M$3*E12+$M$2*I12+$M$1*J12 -> 0
A13: 7 | B13: Anazilsa Sacramento | C13: ='Ficha 1'!T12 -> 0 | D13: ='Ficha 2'!Q12 -> 0 | E13: =AVERAGE(C13:D13) -> 0 | F13: ='Teste 1'!R11 -> 0 | G13: ='Teste 2'!O11 -> 0 | H13: ='Teste 3'!O11 -> 0 | I13: =AVERAGE(F13:H13) -> 0 | J13: =Presenças!AH13 -> 0 | K13: =$M$3*E13+$M$2*I13+$M$1*J13 -> 0
A14: 8 | B14: Anylson Oliveira | C14: ='Ficha 1'!T13 -> 0 | D14: ='Ficha 2'!Q13 -> 0 | E14: =AVERAGE(C14:D14) -> 0 | F14: ='Teste 1'!R12 -> 0 | G14: ='Teste 2'!O12 -> 0 | H14: ='Teste 3'!O12 -> 0 | I14: =AVERAGE(F14:H14) -> 0 | J14: =Presenças!AH14 -> 0 | K14: =$M$3*E14+$M$2*I14+$M$1*J14 -> 0
A15: 9 | B15: Atanásio Quaresma | C15: ='Ficha 1'!T14 -> 0 | D15: ='Ficha 2'!Q14 -> 0 | E15: =AVERAGE(C15:D15) -> 0 | F15: ='Teste 1'!R13 -> 0 | G15: ='Teste 2'!O13 -> 0 | H15: ='Teste 3'!O13 -> 0 | I15: =AVERAGE(F15:H15) -> 0 | J15: =Presenças!AH15 -> 0 | K15: =$M$3*E15+$M$2*I15+$M$1*J15 -> 0
A16: 10 | B16: Carla Nascimento | C16: ='Ficha 1'!T15 -> 0 | D16: ='Ficha 2'!Q15 -> 0 | E16: =AVERAGE(C16:D16) -> 0 | F16: ='Teste 1'!R14 -> 0 | G16: ='Teste 2'!O14 -> 0 | H16: ='Teste 3'!O14 -> 0 | I16: =AVERAGE(F16:H16) -> 0 | J16: =Presenças!AH16 -> 0 | K16: =$M$3*E16+$M$2*I16+$M$1*J16 -> 0
A17: 11 | B17: Celeste Cruz | C17: ='Ficha 1'!T16 -> 0 | D17: ='Ficha 2'!Q16 -> 0 | E17: =AVERAGE(C17:D17) -> 0 | F17: ='Teste 1'!R15 -> 0 | G17: ='Teste 2'!O15 -> 0 | H17: ='Teste 3'!O15 -> 0 | I17: =AVERAGE(F17:H17) -> 0 | J17: =Presenças!AH17 -> 0 | K17: =$M$3*E17+$M$2*I17+$M$1*J17 -> 0
A18: 12 | B18: Célia Assunção | C18: ='Ficha 1'!T17 -> 0 | D18: ='Ficha 2'!Q17 -> 0 | E18: =AVERAGE(C18:D18) -> 0 | F18: ='Teste 1'!R16 -> 0 | G18: ='Teste 2'!O16 -> 0 | H18: ='Teste 3'!O16 -> 0 | I18: =AVERAGE(F18:H18) -> 0 | J18: =Presenças!AH18 -> 0 | K18: =$M$3*E18+$M$2*I18+$M$1*J18 -> 0
... A44: 38 | B44: Yara Paquete | C44: ='Ficha 1'!T43 -> 0 | D44: ='Ficha 2'!Q43 -> 0 | E44: =AVERAGE(C44:D44) -> 0 | F44: ='Teste 1'!R42 -> 0 | G44: ='Teste 2'!O42 -> 0 | H44: ='Teste 3'!O42 -> 0 | I44: =AVERAGE(F44:H44) -> 0 | J44: =Presenças!AH44 -> 0 | K44: =$M$3*E44+$M$2*I44+$M$1*J44 -> 0

Sheet Ficha 1
A1: Álgebra Linear - 1.º Ano - Licenciatura em Matemática - 2025/2026
C2: Parte 1- Anton & Rorres | H2: Parte 2- Anton & Rorres
A3: Ficha 1 | C3: p. 23 | H3: p. 36 | K3: p. 49 | M3: p. 59 | O3: p. 65 | Q3: pp. 84-85
B4: cotação | C4: 1 | D4: 1 | E4: 1 | F4: 1 | G4: 1 | H4: 1 | I4: 1 | J4: 1 | K4: 1 | L4: 1 | M4: 1 | N4: 2 | O4: 2 | P4: 1 | Q4: 2 | R4: 1 | S4: 1 | T4: =SUM(C4:S4) -> 20
A5: N.º | B5: Nome | C5: 4.a | D5: 4.b | E5: 6 | F5: 7 | G5: 21 | H5: 4.a | I5: 11.a | J5: 13.a | K5: 4 | L5: 7 | M5: 12 | N5: 13 | O5: 4 | P5: 5 | Q5: 1 | R5: 13 | S5: 16 | T5: Total | U5: Qualitativo
A6: 1 | B6: ='Balanço - Relatório'!B7 -> Adelino Ceita | T6: =SUM(C6:S6) -> 0 | U6: =IF(T6>=18,"M. Bom",IF(T6>=14,"Bom",IF(T6>=10,"Suf.","Insuf"))) -> Insuf
A7: 2 | B7: ='Balanço - Relatório'!B8 -> Adilson Santos | T7: =SUM(C7:S7) -> 0 | U7: =IF(T7>=18,"M. Bom",IF(T7>=14,"Bom",IF(T7>=10,"Suf.","Insuf"))) -> Insuf
A8: 3 | B8: ='Balanço - Relatório'!B9 -> Admilson Fonseca | T8: =SUM(C8:S8) -> 0 | U8: =IF(T8>=18,"M. Bom",IF(T8>=14,"Bom",IF(T8>=10,"Suf.","Insuf"))) -> Insuf
A9: 4 | B9: ='Balanço - Relatório'!B10 -> Admilton Barros | T9: =SUM(C9:S9) -> 0 | U9: =IF(T9>=18,"M. Bom",IF(T9>=14,"Bom",IF(T9>=10,"Suf.","Insuf"))) -> Insuf
A10: 5 | B10: ='Balanço - Relatório'!B11 -> Adnalda Cosme | T10: =SUM(C10:S10) -> 0 | U10: =IF(T10>=18,"M. Bom",IF(T10>=14,"Bom",IF(T10>=10,"Suf.","Insuf"))) -> Insuf
A11: 6 | B11: ='Balanço - Relatório'!B12 -> Alex Santos | T11: =SUM(C11:S11) -> 0 | U11: =IF(T11>=18,"M. Bom",IF(T11>=14,"Bom",IF(T11>=10,"Suf.","Insuf"))) -> Insuf
A12: 7 | B12: ='Balanço - Relatório'!B13 -> Anazilsa Sacramento | T12: =SUM(C12:S12) -> 0 | U12: =IF(T12>=18,"M. Bom",IF(T12>=14,"Bom",IF(T12>=10,"Suf.","Insuf"))) -> Insuf
A13: 8 | B13: ='Balanço - Relatório'!B14 -> Anylson Oliveira | T13: =SUM(C13:S13) -> 0 | U13: =IF(T13>=18,"M. Bom",IF(T13>=14,"Bom",IF(T13>=10,"Suf.","Insuf"))) -> Insuf
A14: 9 | B14: ='Balanço - Relatório'!B15 -> Atanásio Quaresma | T14: =SUM(C14:S14) -> 0 | U14: =IF(T14>=18,"M. Bom",IF(T14>=14,"Bom",IF(T14>=10,"Suf.","Insuf"))) -> Insuf
A15: 10 | B15: ='Balanço - Relatório'!B16 -> Carla Nascimento | T15: =SUM(C15:S15) -> 0 | U15: =IF(T15>=18,"M. Bom",IF(T15>=14,"Bom",IF(T15>=10,"Suf.","Insuf"))) -> Insuf
A16: 11 | B16: ='Balanço - Relatório'!B17 -> Celeste Cruz | T16: =SUM(C16:S16) -> 0 | U16: =IF(T16>=18,"M. Bom",IF(T16>=14,"Bom",IF(T16>=10,"Suf.","Insuf"))) -> Insuf
A17: 12 | B17: ='Balanço - Relatório'!B18 -> Célia Assunção | T17: =SUM(C17:S17) -> 0 | U17: =IF(T17>=18,"M. Bom",IF(T17>=14,"Bom",IF(T17>=10,"Suf.","Insuf"))) -> Insuf
... A43: 38 | B43: ='Balanço - Relatório'!B44 -> Yara Paquete | T43: =SUM(C43:S43) -> 0 | U43: =IF(T43>=18,"M. Bom",IF(T43>=14,"Bom",IF(T43>=10,"Suf.","Insuf"))) -> Insuf
C46: =SUM(C6:C44)/(COUNT(C6:C44)*C4) -> #DIV/0! | D46: =SUM(D6:D44)/(COUNT(D6:D44)*D4) -> #DIV/0! | E46: =SUM(E6:E44)/(COUNT(E6:E44)*E4) -> #DIV/0! | F46: =SUM(F6:F44)/(COUNT(F6:F44)*F4) -> #DIV/0! | G46: =SUM(G6:G44)/(COUNT(G6:G44)*G4) -> #DIV/0! | H46: =SUM(H6:H44)/(COUNT(H6:H44)*H4) -> #DIV/0! | I46: =SUM(I6:I44)/(COUNT(I6:I44)*I4) -> #DIV/0! | J46: =SUM(J6:J44)/(COUNT(J6:J44)*J4) -> #DIV/0! | ... S46: =SUM(S6:S44)/(COUNT(S6:S44)*S4) -> #DIV/0!

Sheet Ficha 2
A1: Álgebra Linear - 1.º Ano - Licenciatura em Matemática - 2025/2026
C2: Parte 1- Anton & Rorres | G2: Parte 2- Anton & Rorres
A3: Ficha 2 | C3: p. 99 e p. 115 | G3: p. 189 | H3: p. 199 | J3: p. 216 | L3: p. 222 | N3: p. 303
B4: cotação | C4: 1 | D4: 2 | E4: 2 | F4: 2 | G4: 1 | H4: 1 | I4: 1 | J4: 1 | K4: 1 | L4: 1 | M4: 2 | N4: 2 | O4: 1 | P4: 2 | Q4: =SUM(C4:P4) -> 20
A5: N.º | B5: Nome | C5: 21 | D5: 19 | E5: 24 | F5: 25 | G5: 7 | H5: 1.a | I5: 2 | J5: 1 | K5: 2 | L5: 1.b | M5: 2.a | N5: 1 | O5: 3.a | P5: 4 | Q5: Total | R5: Qualitativo
A6: 1 | B6: ='Balanço - Relatório'!B7 -> Adelino Ceita | Q6: =SUM(C6:P6) -> 0 | R6: =IF(Q6>=18,"M. Bom",IF(Q6>=14,"Bom",IF(Q6>=10,"Suf.","Insuf"))) -> Insuf
A7: 2 | B7: ='Balanço - Relatório'!B8 -> Adilson Santos | Q7: =SUM(C7:P7) -> 0 | R7: =IF(Q7>=18,"M. Bom",IF(Q7>=14,"Bom",IF(Q7>=10,"Suf.","Insuf"))) -> Insuf
A8: 3 | B8: ='Balanço - Relatório'!B9 -> Admilson Fonseca | Q8: =SUM(C8:P8) -> 0 | R8: =IF(Q8>=18,"M. Bom",IF(Q8>=14,"Bom",IF(Q8>=10,"Suf.","Insuf"))) -> Insuf
A9: 4 | B9: ='Balanço - Relatório'!B10 -> Admilton Barros | Q9: =SUM(C9:P9) -> 0 | R9: =IF(Q9>=18,"M. Bom",IF(Q9>=14,"Bom",IF(Q9>=10,"Suf.","Insuf"))) -> Insuf
A10: 5 | B10: ='Balanço - Relatório'!B11 -> Adnalda Cosme | Q10: =SUM(C10:P10) -> 0 | R10: =IF(Q10>=18,"M. Bom",IF(Q10>=14,"Bom",IF(Q10>=10,"Suf.","Insuf"))) -> Insuf
A11: 6 | B11: ='Balanço - Relatório'!B12 -> Alex Santos | Q11: =SUM(C11:P11) -> 0 | R11: =IF(Q11>=18,"M. Bom",IF(Q11>=14,"Bom",IF(Q11>=10,"Suf.","Insuf"))) -> Insuf
A12: 7 | B12: ='Balanço - Relatório'!B13 -> Anazilsa Sacramento | Q12: =SUM(C12:P12) -> 0 | R12: =IF(Q12>=18,"M. Bom",IF(Q12>=14,"Bom",IF(Q12>=10,"Suf.","Insuf"))) -> Insuf
A13: 8 | B13: ='Balanço - Relatório'!B14 -> Anylson Oliveira | Q13: =SUM(C13:P13) -> 0 | R13: =IF(Q13>=18,"M. Bom",IF(Q13>=14,"Bom",IF(Q13>=10,"Suf.","Insuf"))) -> Insuf
A14: 9 | B14: ='Balanço - Relatório'!B15 -> Atanásio Quaresma | Q14: =SUM(C14:P14) -> 0 | R14: =IF(Q14>=18,"M. Bom",IF(Q14>=14,"Bom",IF(Q14>=10,"Suf.","Insuf"))) -> Insuf
A15: 10 | B15: ='Balanço - Relatório'!B16 -> Carla Nascimento | Q15: =SUM(C15:P15) -> 0 | R15: =IF(Q15>=18,"M. Bom",IF(Q15>=14,"Bom",IF(Q15>=10,"Suf.","Insuf"))) -> Insuf
A16: 11 | B16: ='Balanço - Relatório'!B17 -> Celeste Cruz | Q16: =SUM(C16:P16) -> 0 | R16: =IF(Q16>=18,"M. Bom",IF(Q16>=14,"Bom",IF(Q16>=10,"Suf.","Insuf"))) -> Insuf
A17: 12 | B17: ='Balanço - Relatório'!B18 -> Célia Assunção | Q17: =SUM(C17:P17) -> 0 | R17: =IF(Q17>=18,"M. Bom",IF(Q17>=14,"Bom",IF(Q17>=10,"Suf.","Insuf"))) -> Insuf
... A43: 38 | B43: ='Balanço - Relatório'!B44 -> Yara Paquete | Q43: =SUM(C43:P43) -> 0 | R43: =IF(Q43>=18,"M. Bom",IF(Q43>=14,"Bom",IF(Q43>=10,"Suf.","Insuf"))) -> Insuf
C46: =SUM(C6:C44)/(COUNT(C6:C44)*C4) -> #DIV/0! | D46: =SUM(D6:D44)/(COUNT(D6:D44)*D4) -> #DIV/0! | E46: =SUM(E6:E44)/(COUNT(E6:E44)*E4) -> #DIV/0! | F46: =SUM(F6:F44)/(COUNT(F6:F44)*F4) -> #DIV/0! | G46: =SUM(G6:G44)/(COUNT(G6:G44)*G4) -> #DIV/0! | H46: =SUM(H6:H44)/(COUNT(H6:H44)*H4) -> #DIV/0! | I46: =SUM(I6:I44)/(COUNT(I6:I44)*I4) -> #DIV/0! | J46: =SUM(J6:J44)/(COUNT(J6:J44)*J4) -> #DIV/0! | ... P46: =SUM(P6:P44)/(COUNT(P6:P44)*P4) -> #DIV/0!

Sheet Teste 1
A1: Álgebra Linear - 1.º Ano - Licenciatura em Matemática - 2025/2026
A3: Teste 1 | B3: cotação | C3: 10 | D3: 30 | E3: 10 | F3: 10 | G3: 10 | H3: 10 | I3: 10 | J3: 10 | K3: 20 | L3: 20 | M3: 20 | N3: 10 | O3: 10 | P3: 10 | Q3: 10 | R3: =SUM(C3:Q3) -> 200
A4: N.º | B4: Nome | C4: 45658 | D4: 45659 | E4: 45660 | F4: 2.1.a | G4: 2.1.b | H4: 2.1.c | I4: 2.1.d | J4: 45690 | K4: 45717 | L4: 45718 | M4: 45748 | N4: 45749 | O4: 45778 | P4: 45779 | Q4: 45780 | R4: Total | S4: Qualitativo
A5: 1 | B5: Adelino Ceita | R5: =SUM(C5:Q5)/10 -> 0 | S5: =IF(R5>=18,"M. Bom",IF(R5>=14,"Bom",IF(R5>=10,"Suf.","Insuf"))) -> Insuf
A6: 2 | B6: Adilson Santos | R6: =SUM(C6:Q6)/10 -> 0 | S6: =IF(R6>=18,"M. Bom",IF(R6>=14,"Bom",IF(R6>=10,"Suf.","Insuf"))) -> Insuf
A7: 3 | B7: Admilson Fonseca | R7: =SUM(C7:Q7)/10 -> 0 | S7: =IF(R7>=18,"M. Bom",IF(R7>=14,"Bom",IF(R7>=10,"Suf.","Insuf"))) -> Insuf
A8: 4 | B8: Admilton Barros | R8: =SUM(C8:Q8)/10 -> 0 | S8: =IF(R8>=18,"M. Bom",IF(R8>=14,"Bom",IF(R8>=10,"Suf.","Insuf"))) -> Insuf
A9: 5 | B9: Adnalda Cosme | R9: =SUM(C9:Q9)/10 -> 0 | S9: =IF(R9>=18,"M. Bom",IF(R9>=14,"Bom",IF(R9>=10,"Suf.","Insuf"))) -> Insuf
B10: Alex Santos | R10: =SUM(C10:Q10)/10 -> 0 | S10: =IF(R10>=18,"M. Bom",IF(R10>=14,"Bom",IF(R10>=10,"Suf.","Insuf"))) -> Insuf
A11: 6 | B11: Anazilsa Sacramento | R11: =SUM(C11:Q11)/10 -> 0 | S11: =IF(R11>=18,"M. Bom",IF(R11>=14,"Bom",IF(R11>=10,"Suf.","Insuf"))) -> Insuf
A12: 7 | B12: Anylson Oliveira | R12: =SUM(C12:Q12)/10 -> 0 | S12: =IF(R12>=18,"M. Bom",IF(R12>=14,"Bom",IF(R12>=10,"Suf.","Insuf"))) -> Insuf
A13: 8 | B13: Atanásio Quaresma | R13: =SUM(C13:Q13)/10 -> 0 | S13: =IF(R13>=18,"M. Bom",IF(R13>=14,"Bom",IF(R13>=10,"Suf.","Insuf"))) -> Insuf
A14: 9 | B14: Carla Nascimento | R14: =SUM(C14:Q14)/10 -> 0 | S14: =IF(R14>=18,"M. Bom",IF(R14>=14,"Bom",IF(R14>=10,"Suf.","Insuf"))) -> Insuf
A15: 10 | B15: Celeste Cruz | R15: =SUM(C15:Q15)/10 -> 0 | S15: =IF(R15>=18,"M. Bom",IF(R15>=14,"Bom",IF(R15>=10,"Suf.","Insuf"))) -> Insuf
A16: 11 | B16: Célia Assunção | R16: =SUM(C16:Q16)/10 -> 0 | S16: =IF(R16>=18,"M. Bom",IF(R16>=14,"Bom",IF(R16>=10,"Suf.","Insuf"))) -> Insuf
A17: 12 | B17: Celso Rosário | R17: =SUM(C17:Q17)/10 -> 0 | S17: =IF(R17>=18,"M. Bom",IF(R17>=14,"Bom",IF(R17>=10,"Suf.","Insuf"))) -> Insuf
A18: 13 | B18: Cristina Espírito Santo | R18: =SUM(C18:Q18)/10 -> 0 | S18: =IF(R18>=18,"M. Bom",IF(R18>=14,"Bom",IF(R18>=10,"Suf.","Insuf"))) -> Insuf
A19: 14 | B19: Dies Varela | R19: =SUM(C19:Q19)/10 -> 0 | S19: =IF(R19>=18,"M. Bom",IF(R19>=14,"Bom",IF(R19>=10,"Suf.","Insuf"))) -> Insuf
A20: 15 | B20: Edcarlos Fernandes | R20: =SUM(C20:Q20)/10 -> 0 | S20: =IF(R20>=18,"M. Bom",IF(R20>=14,"Bom",IF(R20>=10,"Suf.","Insuf"))) -> Insuf
A21: 16 | B21: Edulay Neves | R21: =SUM(C21:Q21)/10 -> 0 | S21: =IF(R21>=18,"M. Bom",IF(R21>=14,"Bom",IF(R21>=10,"Suf.","Insuf"))) -> Insuf
A22: 17 | B22: Eliseo Luís | R22: =SUM(C22:Q22)/10 -> 0 | S22: =IF(R22>=18,"M. Bom",IF(R22>=14,"Bom",IF(R22>=10,"Suf.","Insuf"))) -> Insuf
... A42: 38 | B42: Yara Paquete | R42: =SUM(C42:Q42)/10 -> 0 | S42: =IF(R42>=18,"M. Bom",IF(R42>=14,"Bom",IF(R42>=10,"Suf.","Insuf"))) -> Insuf
C45: =SUM(C5:C43)/(COUNT(C5:C43)*C3) -> #DIV/0! | D45: =SUM(D5:D43)/(COUNT(D5:D43)*D3) -> #DIV/0! | E45: =SUM(E5:E43)/(COUNT(E5:E43)*E3) -> #DIV/0! | F45: =SUM(F5:F43)/(COUNT(F5:F43)*F3) -> #DIV/0! | G45: =SUM(G5:G43)/(COUNT(G5:G43)*G3) -> #DIV/0! | H45: =SUM(H5:H43)/(COUNT(H5:H43)*H3) -> #DIV/0! | I45: =SUM(I5:I43)/(COUNT(I5:I43)*I3) -> #DIV/0! | J45: =SUM(J5:J43)/(COUNT(J5:J43)*J3) -> #DIV/0! | ... Q45: =SUM(Q5:Q43)/(COUNT(Q5:Q43)*Q3) -> #DIV/0!

Sheet Teste 2
A1: Álgebra Linear - 1.º Ano - Licenciatura em Matemática - 2025/2026
A3: Teste 2 | B3: cotação | C3: 10 | D3: 20 | E3: 30 | F3: 20 | G3: 15 | H3: 20 | I3: 20 | J3: 20 | K3: 5 | L3: 20 | M3: 10 | N3: 10 | O3: =SUM(C3:N3) -> 200
A4: N.º | B4: Nome | C4: 45658 | D4: 45659 | E4: 45660 | F4: 2. | G4: 3. | H4: 45748 | I4: 45749 | J4: 45778 | K4: 45779 | L4: 45809 | M4: 45810 | N4: 45811 | O4: Total | P4: Qualitativo
A5: 1 | B5: Adelino Ceita | O5: =SUM(C5:N5)/10 -> 0 | P5: =IF(O5>=18,"M. Bom",IF(O5>=14,"Bom",IF(O5>=10,"Suf.","Insuf"))) -> Insuf
A6: 2 | B6: Adilson Santos | O6: =SUM(C6:N6)/10 -> 0 | P6: =IF(O6>=18,"M. Bom",IF(O6>=14,"Bom",IF(O6>=10,"Suf.","Insuf"))) -> Insuf
A7: 3 | B7: Admilson Fonseca | O7: =SUM(C7:N7)/10 -> 0 | P7: =IF(O7>=18,"M. Bom",IF(O7>=14,"Bom",IF(O7>=10,"Suf.","Insuf"))) -> Insuf
A8: 4 | B8: Admilton Barros | O8: =SUM(C8:N8)/10 -> 0 | P8: =IF(O8>=18,"M. Bom",IF(O8>=14,"Bom",IF(O8>=10,"Suf.","Insuf"))) -> Insuf
A9: 5 | B9: Adnalda Cosme | O9: =SUM(C9:N9)/10 -> 0 | P9: =IF(O9>=18,"M. Bom",IF(O9>=14,"Bom",IF(O9>=10,"Suf.","Insuf"))) -> Insuf
B10: Alex Santos | O10: =SUM(C10:N10)/10 -> 0 | P10: =IF(O10>=18,"M. Bom",IF(O10>=14,"Bom",IF(O10>=10,"Suf.","Insuf"))) -> Insuf
A11: 6 | B11: Anazilsa Sacramento | O11: =SUM(C11:N11)/10 -> 0 | P11: =IF(O11>=18,"M. Bom",IF(O11>=14,"Bom",IF(O11>=10,"Suf.","Insuf"))) -> Insuf
A12: 7 | B12: Anylson Oliveira | O12: =SUM(C12:N12)/10 -> 0 | P12: =IF(O12>=18,"M. Bom",IF(O12>=14,"Bom",IF(O12>=10,"Suf.","Insuf"))) -> Insuf
A13: 8 | B13: Atanásio Quaresma | O13: =SUM(C13:N13)/10 -> 0 | P13: =IF(O13>=18,"M. Bom",IF(O13>=14,"Bom",IF(O13>=10,"Suf.","Insuf"))) -> Insuf
A14: 9 | B14: Carla Nascimento | O14: =SUM(C14:N14)/10 -> 0 | P14: =IF(O14>=18,"M. Bom",IF(O14>=14,"Bom",IF(O14>=10,"Suf.","Insuf"))) -> Insuf
A15: 10 | B15: Celeste Cruz | O15: =SUM(C15:N15)/10 -> 0 | P15: =IF(O15>=18,"M. Bom",IF(O15>=14,"Bom",IF(O15>=10,"Suf.","Insuf"))) -> Insuf
A16: 11 | B16: Célia Assunção | O16: =SUM(C16:N16)/10 -> 0 | P16: =IF(O16>=18,"M. Bom",IF(O16>=14,"Bom",IF(O16>=10,"Suf.","Insuf"))) -> Insuf
A17: 12 | B17: Celso Rosário | O17: =SUM(C17:N17)/10 -> 0 | P17: =IF(O17>=18,"M. Bom",IF(O17>=14,"Bom",IF(O17>=10,"Suf.","Insuf"))) -> Insuf
A18: 13 | B18: Cristina Espírito Santo | O18: =SUM(C18:N18)/10 -> 0 | P18: =IF(O18>=18,"M. Bom",IF(O18>=14,"Bom",IF(O18>=10,"Suf.","Insuf"))) -> Insuf
A19: 14 | B19: Dies Varela | O19: =SUM(C19:N19)/10 -> 0 | P19: =IF(O19>=18,"M. Bom",IF(O19>=14,"Bom",IF(O19>=10,"Suf.","Insuf"))) -> Insuf
A20: 15 | B20: Edcarlos Fernandes | O20: =SUM(C20:N20)/10 -> 0 | P20: =IF(O20>=18,"M. Bom",IF(O20>=14,"Bom",IF(O20>=10,"Suf.","Insuf"))) -> Insuf
A21: 16 | B21: Edulay Neves | O21: =SUM(C21:N21)/10 -> 0 | P21: =IF(O21>=18,"M. Bom",IF(O21>=14,"Bom",IF(O21>=10,"Suf.","Insuf"))) -> Insuf
A22: 17 | B22: Eliseo Luís | O22: =SUM(C22:N22)/10 -> 0 | P22: =IF(O22>=18,"M. Bom",IF(O22>=14,"Bom",IF(O22>=10,"Suf.","Insuf"))) -> Insuf
... A42: 38 | B42: Yara Paquete | O42: =SUM(C42:N42)/10 -> 0 | P42: =IF(O42>=18,"M. Bom",IF(O42>=14,"Bom",IF(O42>=10,"Suf.","Insuf"))) -> Insuf
C45: =SUM(C5:C43)/(COUNT(C5:C43)*C3) -> #DIV/0! | D45: =SUM(D5:D43)/(COUNT(D5:D43)*D3) -> #DIV/0! | E45: =SUM(E5:E43)/(COUNT(E5:E43)*E3) -> #DIV/0! | F45: =SUM(F5:F43)/(COUNT(F5:F43)*F3) -> #DIV/0! | G45: =SUM(G5:G43)/(COUNT(G5:G43)*G3) -> #DIV/0! | H45: =SUM(H5:H43)/(COUNT(H5:H43)*H3) -> #DIV/0! | I45: =SUM(I5:I43)/(COUNT(I5:I43)*I3) -> #DIV/0! | J45: =SUM(J5:J43)/(COUNT(J5:J43)*J3) -> #DIV/0! | ... N45: =SUM(N5:N43)/(COUNT(N5:N43)*N3) -> #DIV/0!

Sheet Teste 3
A1: Álgebra Linear - 1.º Ano - Licenciatura em Matemática - 2025/2026
A3: Teste 3 | B3: cotação | C3: 20 | D3: 20 | E3: 20 | F3: 20 | G3: 15 | H3: 15 | I3: 20 | J3: 10 | K3: 20 | L3: 10 | M3: 15 | N3: 15 | O3: =SUM(C3:N3) -> 200
A4: N.º | B4: Nome | C4: 45658 | D4: 45659 | E4: 45660 | F4: 46054 | G4: 46055 | H4: 46056 | I4: 46082 | J4: 46083 | K4: 46113 | L4: 46114 | M4: 46143 | N4: 46144 | O4: Total | P4: Qualitativo
A5: 1 | B5: Adelino Ceita | O5: =SUM(C5:N5)/10 -> 0 | P5: =IF(O5>=18,"M. Bom",IF(O5>=14,"Bom",IF(O5>=10,"Suf.","Insuf"))) -> Insuf
A6: 2 | B6: Adilson Santos | O6: =SUM(C6:N6)/10 -> 0 | P6: =IF(O6>=18,"M. Bom",IF(O6>=14,"Bom",IF(O6>=10,"Suf.","Insuf"))) -> Insuf
A7: 3 | B7: Admilson Fonseca | O7: =SUM(C7:N7)/10 -> 0 | P7: =IF(O7>=18,"M. Bom",IF(O7>=14,"Bom",IF(O7>=10,"Suf.","Insuf"))) -> Insuf
A8: 4 | B8: Admilton Barros | O8: =SUM(C8:N8)/10 -> 0 | P8: =IF(O8>=18,"M. Bom",IF(O8>=14,"Bom",IF(O8>=10,"Suf.","Insuf"))) -> Insuf
A9: 5 | B9: Adnalda Cosme | O9: =SUM(C9:N9)/10 -> 0 | P9: =IF(O9>=18,"M. Bom",IF(O9>=14,"Bom",IF(O9>=10,"Suf.","Insuf"))) -> Insuf
B10: Alex Santos | O10: =SUM(C10:N10)/10 -> 0 | P10: =IF(O10>=18,"M. Bom",IF(O10>=14,"Bom",IF(O10>=10,"Suf.","Insuf"))) -> Insuf
A11: 6 | B11: Anazilsa Sacramento | O11: =SUM(C11:N11)/10 -> 0 | P11: =IF(O11>=18,"M. Bom",IF(O11>=14,"Bom",IF(O11>=10,"Suf.","Insuf"))) -> Insuf
A12: 7 | B12: Anylson Oliveira | O12: =SUM(C12:N12)/10 -> 0 | P12: =IF(O12>=18,"M. Bom",IF(O12>=14,"Bom",IF(O12>=10,"Suf.","Insuf"))) -> Insuf
A13: 8 | B13: Atanásio Quaresma | O13: =SUM(C13:N13)/10 -> 0 | P13: =IF(O13>=18,"M. Bom",IF(O13>=14,"Bom",IF(O13>=10,"Suf.","Insuf"))) -> Insuf
A14: 9 | B14: Carla Nascimento | O14: =SUM(C14:N14)/10 -> 0 | P14: =IF(O14>=18,"M. Bom",IF(O14>=14,"Bom",IF(O14>=10,"Suf.","Insuf"))) -> Insuf
A15: 10 | B15: Celeste Cruz | O15: =SUM(C15:N15)/10 -> 0 | P15: =IF(O15>=18,"M. Bom",IF(O15>=14,"Bom",IF(O15>=10,"Suf.","Insuf"))) -> Insuf
A16: 11 | B16: Célia Assunção | O16: =SUM(C16:N16)/10 -> 0 | P16: =IF(O16>=18,"M. Bom",IF(O16>=14,"Bom",IF(O16>=10,"Suf.","Insuf"))) -> Insuf
A17: 12 | B17: Celso Rosário | O17: =SUM(C17:N17)/10 -> 0 | P17: =IF(O17>=18,"M. Bom",IF(O17>=14,"Bom",IF(O17>=10,"Suf.","Insuf"))) -> Insuf
A18: 13 | B18: Cristina Espírito Santo | O18: =SUM(C18:N18)/10 -> 0 | P18: =IF(O18>=18,"M. Bom",IF(O18>=14,"Bom",IF(O18>=10,"Suf.","Insuf"))) -> Insuf
A19: 14 | B19: Dies Varela | O19: =SUM(C19:N19)/10 -> 0 | P19: =IF(O19>=18,"M. Bom",IF(O19>=14,"Bom",IF(O19>=10,"Suf.","Insuf"))) -> Insuf
A20: 15 | B20: Edcarlos Fernandes | O20: =SUM(C20:N20)/10 -> 0 | P20: =IF(O20>=18,"M. Bom",IF(O20>=14,"Bom",IF(O20>=10,"Suf.","Insuf"))) -> Insuf
A21: 16 | B21: Edulay Neves | O21: =SUM(C21:N21)/10 -> 0 | P21: =IF(O21>=18,"M. Bom",IF(O21>=14,"Bom",IF(O21>=10,"Suf.","Insuf"))) -> Insuf
A22: 17 | B22: Eliseo Luís | O22: =SUM(C22:N22)/10 -> 0 | P22: =IF(O22>=18,"M. Bom",IF(O22>=14,"Bom",IF(O22>=10,"Suf.","Insuf"))) -> Insuf
... A42: 38 | B42: Yara Paquete | O42: =SUM(C42:N42)/10 -> 0 | P42: =IF(O42>=18,"M. Bom",IF(O42>=14,"Bom",IF(O42>=10,"Suf.","Insuf"))) -> Insuf
C45: =SUM(C5:C43)/(COUNT(C5:C43)*C3) -> #DIV/0! | D45: =SUM(D5:D43)/(COUNT(D5:D43)*D3) -> #DIV/0! | E45: =SUM(E5:E43)/(COUNT(E5:E43)*E3) -> #DIV/0! | F45: =SUM(F5:F43)/(COUNT(F5:F43)*F3) -> #DIV/0! | G45: =SUM(G5:G43)/(COUNT(G5:G43)*G3) -> #DIV/0! | H45: =SUM(H5:H43)/(COUNT(H5:H43)*H3) -> #DIV/0! | I45: =SUM(I5:I43)/(COUNT(I5:I43)*I3) -> #DIV/0! | J45: =SUM(J5:J43)/(COUNT(J5:J43)*J3) -> #DIV/0! | ... N45: =SUM(N5:N43)/(COUNT(N5:N43)*N3) -> #DIV/0!

Sheet Exame
A1: Álgebra Linear - 1.º Ano - Licenciatura em Matemática - 2025/2026
S2: 31 | T2: presenças
A3: Exame | B3: cotação | C3: 10 | D3: 25 | E3: 15 | F3: 15 | G3: 15 | H3: 10 | I3: 15 | J3: 15 | K3: 15 | L3: 15 | M3: 10 | N3: 15 | O3: 10 | P3: 15 | Q3: =SUM(C3:P3) -> 200
A4: N.º | B4: Nome | C4: 45658 | D4: 45659 | E4: 45660 | F4: 2. | G4: 3. | H4: 46113 | I4: 46114 | J4: 46143 | K4: 46144 | L4: 46145 | M4: 46146 | N4: 46174 | O4: 46175 | P4: 7. | Q4: Total | R4: Qualitativo
A5: 1 | B5: Adelino Ceita | Q5: =SUM(C5:P5)/10 -> 0 | S5: Faltou
B6: Alex Santos | Q6: =SUM(C6:P6)/10 -> 0 | R6: =IF(Q6>=18,"M. Bom",IF(Q6>=14,"Bom",IF(Q6>=10,"Suf.","Insuf"))) -> Insuf | S6: 3.º Ano
A7: 13 | B7: Cristina Espírito Santo | Q7: =SUM(C7:P7)/10 -> 0 | R7: =IF(Q7>=18,"M. Bom",IF(Q7>=14,"Bom",IF(Q7>=10,"Suf.","Insuf"))) -> Insuf
A8: 14 | B8: Dies Varela | Q8: =SUM(C8:P8)/10 -> 0 | R8: =IF(Q8>=18,"M. Bom",IF(Q8>=14,"Bom",IF(Q8>=10,"Suf.","Insuf"))) -> Insuf
A9: 16 | B9: Edulay Neves | Q9: =SUM(C9:P9)/10 -> 0 | R9: =IF(Q9>=18,"M. Bom",IF(Q9>=14,"Bom",IF(Q9>=10,"Suf.","Insuf"))) -> Insuf
A10: 18 | B10: Érica Sacramento | Q10: =SUM(C10:P10)/10 -> 0 | R10: =IF(Q10>=18,"M. Bom",IF(Q10>=14,"Bom",IF(Q10>=10,"Suf.","Insuf"))) -> Insuf
A11: 19 | B11: Gerdiley Camblé | Q11: =SUM(C11:P11)/10 -> 0 | R11: =IF(Q11>=18,"M. Bom",IF(Q11>=14,"Bom",IF(Q11>=10,"Suf.","Insuf"))) -> Insuf
A12: 20 | B12: Gilson Boa Morte | Q12: =SUM(C12:P12)/10 -> 0 | R12: =IF(Q12>=18,"M. Bom",IF(Q12>=14,"Bom",IF(Q12>=10,"Suf.","Insuf"))) -> Insuf
A13: 22 | B13: Igualdina Andrade | Q13: =SUM(C13:P13)/10 -> 0 | R13: =IF(Q13>=18,"M. Bom",IF(Q13>=14,"Bom",IF(Q13>=10,"Suf.","Insuf"))) -> Insuf
A14: 23 | B14: Jackwillson Barreto | Q14: =SUM(C14:P14)/10 -> 0 | S14: Faltou
A15: 26 | B15: Jenilson Assunção | Q15: =SUM(C15:P15)/10 -> 0 | S15: Faltou
A16: 29 | B16: Leonardo Quaresma | Q16: =SUM(C16:P16)/10 -> 0 | R16: =IF(Q16>=18,"M. Bom",IF(Q16>=14,"Bom",IF(Q16>=10,"Suf.","Insuf"))) -> Insuf
A17: 31 | B17: Manuel Pontes | Q17: =SUM(C17:P17)/10 -> 0 | R17: =IF(Q17>=18,"M. Bom",IF(Q17>=14,"Bom",IF(Q17>=10,"Suf.","Insuf"))) -> Insuf
A18: 32 | B18: Nelma Espírito Santo | Q18: =SUM(C18:P18)/10 -> 0 | R18: =IF(Q18>=18,"M. Bom",IF(Q18>=14,"Bom",IF(Q18>=10,"Suf.","Insuf"))) -> Insuf
A19: 34 | B19: Susete Santos | Q19: =SUM(C19:P19)/10 -> 0 | R19: =IF(Q19>=18,"M. Bom",IF(Q19>=14,"Bom",IF(Q19>=10,"Suf.","Insuf"))) -> Insuf
A20: 36 | B20: Vanderley Coelho | Q20: =SUM(C20:P20)/10 -> 0 | R20: =IF(Q20>=18,"M. Bom",IF(Q20>=14,"Bom",IF(Q20>=10,"Suf.","Insuf"))) -> Insuf
A21: 37 | B21: Waldney Pereira | Q21: =SUM(C21:P21)/10 -> 0 | R21: =IF(Q21>=18,"M. Bom",IF(Q21>=14,"Bom",IF(Q21>=10,"Suf.","Insuf"))) -> Insuf | S21: 3.º Ano
A22: 38 | B22: Yara Paquete | Q22: =SUM(C22:P22)/10 -> 0 | S22: Faltou
C25: =SUM(C5:C23)/(COUNT(C5:C23)*C3) -> #DIV/0! | D25: =SUM(D5:D23)/(COUNT(D5:D23)*D3) -> #DIV/0! | E25: =SUM(E5:E23)/(COUNT(E5:E23)*E3) -> #DIV/0! | F25: =SUM(F5:F23)/(COUNT(F5:F23)*F3) -> #DIV/0! | G25: =SUM(G5:G23)/(COUNT(G5:G23)*G3) -> #DIV/0! | H25: =SUM(H5:H23)/(COUNT(H5:H23)*H3) -> #DIV/0! | I25: =SUM(I5:I23)/(COUNT(I5:I23)*I3) -> #DIV/0! | J25: =SUM(J5:J23)/(COUNT(J5:J23)*J3) -> #DIV/0! | ... P25: =SUM(P5:P23)/(COUNT(P5:P23)*P3) -> #DIV/0!

Sheet Presenças
A3: Álgebra Linear - 1.º Ano - Licenciatura em Matemática - 2025/2026
C4: Presenças
C5: 1 | E5: 2 | G5: 3 | I5: 4 | K5: 5 | L5: 6 | N5: 7 | P5: 8 | R5: 9 | T5: 10 | V5: 11 | X5: 12 | Z5: 13 | AB5: 14 | AD5: 15
A6: N.º | B6: Nome | C6: 45923 | D6: 45925 | E6: 45930 | F6: 45932 | G6: 45937 | H6: 45939 | I6: 45944 | J6: 45946 | K6: 45951 | L6: 45958 | M6: 45960 | N6: 45965 | O6: 45967 | P6: 45972 | Q6: 45974 | R6: 45979 | S6: 45981 | T6: 45986 | U6: 45988 | V6: 45993 | W6: 45995 | X6: 46000 | Y6: 46002 | Z6: 46007 | AA6: 46009 | AB6: 46028 | AC6: 46030 | AD6: 46035 | AE6: 46037 | AF6: Total | AH6: Nota
A7: 1 | B7: Adelino Ceita | AF7: =SUM(C7:AE7) -> 0 | AG7: =AF7/21 -> 0 | AH7: =AF7*20/20 -> 0
A8: 2 | B8: Adilson Santos | AF8: =SUM(C8:AE8) -> 0 | AG8: =AF8/21 -> 0 | AH8: =AF8*20/20 -> 0
A9: 3 | B9: Admilson Fonseca | AF9: =SUM(C9:AE9) -> 0 | AG9: =AF9/21 -> 0 | AH9: =AF9*20/20 -> 0
A10: 4 | B10: Admilton Barros | AF10: =SUM(C10:AE10) -> 0 | AG10: =AF10/21 -> 0 | AH10: =AF10*20/20 -> 0
A11: 5 | B11: Adnalda Cosme | AF11: =SUM(C11:AE11) -> 0 | AG11: =AF11/21 -> 0 | AH11: =AF11*20/20 -> 0
A12: 6 | B12: Alex Santos | AF12: =SUM(C12:AE12) -> 0 | AG12: =AF12/21 -> 0 | AH12: =AF12*20/20 -> 0
A13: 7 | B13: Anazilsa Sacramento | AF13: =SUM(C13:AE13) -> 0 | AG13: =AF13/21 -> 0 | AH13: =AF13*20/20 -> 0
A14: 8 | B14: Anylson Oliveira | AF14: =SUM(C14:AE14) -> 0 | AG14: =AF14/21 -> 0 | AH14: =AF14*20/20 -> 0
A15: 9 | B15: Atanásio Quaresma | AF15: =SUM(C15:AE15) -> 0 | AG15: =AF15/21 -> 0 | AH15: =AF15*20/20 -> 0
A16: 10 | B16: Carla Nascimento | AF16: =SUM(C16:AE16) -> 0 | AG16: =AF16/21 -> 0 | AH16: =AF16*20/20 -> 0
A17: 11 | B17: Celeste Cruz | AF17: =SUM(C17:AE17) -> 0 | AG17: =AF17/21 -> 0 | AH17: =AF17*20/20 -> 0
A18: 12 | B18: Célia Assunção | AF18: =SUM(C18:AE18) -> 0 | AG18: =AF18/21 -> 0 | AH18: =AF18*20/20 -> 0
... A31: 25 | B31: Jadmilson Rosa | AF31: =SUM(C31:AE31) -> 0 | AG31: =AF31/21 -> 0 | AH31: =AF31*20/20 -> 0
A32: 26 | B32: Jenilson Assunção | AG32: =AF32/21 -> 0 | AH32: =AF32*20/20 -> 0
A33: 27 | B33: Jéssica Martins | AF33: =SUM(C33:AE33) -> 0 | AG33: =AF33/21 -> 0 | AH33: =AF33*20/20 -> 0
A34: 28 | B34: Ledyzer Santos | AF34: =SUM(C34:AE34) -> 0 | AG34: =AF34/21 -> 0 | AH34: =AF34*20/20 -> 0
A35: 29 | B35: Leonardo Quaresma | AF35: =SUM(C35:AE35) -> 0 | AG35: =AF35/21 -> 0 | AH35: =AF35*20/20 -> 0
A36: 30 | B36: Liedson Bonfim | AF36: =SUM(C36:AE36) -> 0 | AG36: =AF36/21 -> 0 | AH36: =AF36*20/20 -> 0
A37: 31 | B37: Manuel Pontes | AF37: =SUM(C37:AE37) -> 0 | AG37: =AF37/21 -> 0 | AH37: =AF37*20/20 -> 0
A38: 32 | B38: Nelma Espírito Santo | AF38: =SUM(C38:AE38) -> 0 | AG38: =AF38/21 -> 0 | AH38: =AF38*20/20 -> 0
A39: 33 | B39: Ray Lima | AF39: =SUM(C39:AE39) -> 0 | AG39: =AF39/21 -> 0 | AH39: =AF39*20/20 -> 0
A40: 34 | B40: Susete Santos | AF40: =SUM(C40:AE40) -> 0 | AG40: =AF40/21 -> 0 | AH40: =AF40*20/20 -> 0
A41: 35 | B41: Valdemiro Coelho | AF41: =SUM(C41:AE41) -> 0 | AG41: =AF41/21 -> 0 | AH41: =AF41*20/20 -> 0
A42: 36 | B42: Vanderley Coelho | AF42: =SUM(C42:AE42) -> 0 | AG42: =AF42/21 -> 0 | AH42: =AF42*20/20 -> 0
A43: 37 | B43: Waldney Pereira | AF43: =SUM(C43:AE43) -> 0 | AG43: =AF43/21 -> 0 | AH43: =AF43*20/20 -> 0
A44: 38 | B44: Yara Paquete | AF44: =SUM(C44:AE44) -> 0 | AG44: =AF44/21 -> 0 | AH44: =AF44*20/20 -> 0
AF45: =SUM(C45:AE45) -> 0
C46: =SUM(C7:C45) -> 0 | D46: =SUM(D7:D45) -> 0 | E46: =SUM(E7:E45) -> 0 | F46: =SUM(F7:F45) -> 0 | G46: =SUM(G7:G45) -> 0 | H46: =SUM(H7:H45) -> 0 | I46: =SUM(I7:I45) -> 0 | J46: =SUM(J7:J45) -> 0 | ... AE46: =SUM(AE7:AE45) -> 0
